Workbook

Sheet Data
A1: 5 | B1: apple | C1: 45306 | E1: x | F1: y | G1: z | H1: 1 | I1: 9 | J1: -100 | K1: 2 | L1: 10 | M1: 1 | O1: Name | P1: Age | Q1: Height | R1: Score | T1: Age | V1: Age | W1: Name | Y1: Name | AA1: Age | AB1: Name | AD1: Age | AF1: Nope | AH1: Score | AI1: Score | AK1: Name | AM1: Age | AO1: Name | AQ1: Name | AS1: Name | AU1: Name | AW1: Score | AY1: Age | AZ1: Name | BA1: Score | BC1: Name | BE1: Name | BF1: 1 | BG1: 4 | BH1: 2
A2: 3 | B2: banana | C2: 45338 | E2: 10 | F2: 20 | G2: 30 | H2: 3 | I2: 7 | J2: 30 | K2: 4 | L2: 20 | M2: =NA() -> #N/A | O2: Ann | P2: 30 | Q2: 160 | R2: 80 | T2: 30 | V2: >25 | W2: B* | Y2: Ann | AA2: >30 | AF2: 1 | AH2: >=80 | AI2: <=90 | AK2: = | AM2: =25 -> 25 | AO2: bob | AQ2: *e | AS2: <>Bob | AW2: >0 | AY2: >26 | BC2: Gus | BE2: Eve | BF2: 4 | BG2: 6 | BH2: 8
A3: 8 | B3: cherry | C3: 45368 | H3: 5 | I3: 5 | J3: 40 | K3: 5 | L3: 30 | M3: 3 | O3: Bob | P3: 25 | Q3: 175 | R3: 90 | Y3: Bob | AA3: <26 | AZ3: B* | BA3: <80 | BF3: 2 | BG3: 7 | BH3: 4
A4: 1 | B4: apple | C4: 45400 | H4: 7 | I4: 3 | J4: 50 | K4: 4 | L4: 40 | M4: a | O4: Cid | P4: 30 | Q4: 180 | R4: 70 | BF4: 6 | BG4: 5 | BH4: 12
A5: 9 | B5: date | C5: 45431 | H5: 9 | I5: 1 | J5: 60 | K5: 5 | L5: =SUBTOTAL(9,L1:L4) -> 100 | O5: Dee | P5: 41 | Q5: 165 | R5: 85 | BF5: 3 | BG5: 3 | BH5: 6
A6: 2 | B6: banana | C6: 45463 | K6: 7 | L6: 5 | O6: Eve | P6: 25 | Q6: 170 | R6: 60 | BF6: 5 | BG6: 2 | BH6: 10
A7: 7 | B7: apple | C7: 45494 | K7: 8 | O7: Fay | P7: 35 | Q7: 158 | R7: 95 | BF7: 9 | BG7: 7 | BH7: 18
A8: 4 | B8: fig | C8: 45526 | K8: 9 | O8: Bob | P8: 52 | Q8: 182 | R8: 77 | BF8: 7 | BG8: 1 | BH8: 14
O9: Gus | P9: n/a | Q9: 170

Sheet Calc
A1: =SUM(Data!A1:A8) -> 39 | B1: SUM(Data!A1:A8)
A2: =AVERAGE(Data!A1:A8) -> 4.875 | B2: AVERAGE(Data!A1:A8)
A3: =MIN(Data!A1:A8) -> 1 | B3: MIN(Data!A1:A8)
A4: =MAX(Data!A1:A8) -> 9 | B4: MAX(Data!A1:A8)
A5: =COUNT(Data!A1:A8) -> 8 | B5: COUNT(Data!A1:A8)
A6: =COUNTA(Data!B1:B9) -> 8 | B6: COUNTA(Data!B1:B9)
A7: =MEDIAN(Data!A1:A8) -> 4.5 | B7: MEDIAN(Data!A1:A8)
A8: =LARGE(Data!A1:A8,2) -> 8 | B8: LARGE(Data!A1:A8,2)
A9: =SMALL(Data!A1:A8,3) -> 3 | B9: SMALL(Data!A1:A8,3)
A10: =PRODUCT(Data!A1:A3) -> 120 | B10: PRODUCT(Data!A1:A3)
A11: =SUMIF(Data!B1:B8,"apple",Data!A1:A8) -> 13 | B11: SUMIF(Data!B1:B8,"apple",Data!A1:A8)
A12: =COUNTIF(Data!B1:B8,"a*") -> 3 | B12: COUNTIF(Data!B1:B8,"a*")
A13: =COUNTIF(Data!A1:A8,">4") -> 4 | B13: COUNTIF(Data!A1:A8,">4")
A14: =COUNTIF(Data!A1:A8,"<>5") -> 7 | B14: COUNTIF(Data!A1:A8,"<>5")
A15: =SUMIFS(Data!A1:A8,Data!B1:B8,"apple",Data!A1:A8,">=5") -> 12 | B15: SUMIFS(Data!A1:A8,Data!B1:B8,"apple",Data!A1:A8,">=5")
A16: =AVERAGEIF(Data!B1:B8,"banana",Data!A1:A8) -> 2.5 | B16: AVERAGEIF(Data!B1:B8,"banana",Data!A1:A8)
A17: =COUNTIFS(Data!B1:B8,"apple",Data!A1:A8,"<6") -> 2 | B17: COUNTIFS(Data!B1:B8,"apple",Data!A1:A8,"<6")
A18: =_xlfn.MAXIFS(Data!A1:A8,Data!B1:B8,"apple") -> 7 | B18: _xlfn.MAXIFS(Data!A1:A8,Data!B1:B8,"apple")
A19: =_xlfn.MINIFS(Data!A1:A8,Data!B1:B8,"apple") -> 1 | B19: _xlfn.MINIFS(Data!A1:A8,Data!B1:B8,"apple")
A20: =SUMPRODUCT(Data!A1:A8,Data!A1:A8) -> 249 | B20: SUMPRODUCT(Data!A1:A8,Data!A1:A8)
A21: =SUMPRODUCT((Data!B1:B8="apple")*(Data!A1:A8)) -> 13 | B21: SUMPRODUCT((Data!B1:B8="apple")*(Data!A1:A8))
A22: =COUNTBLANK(Data!B1:B9) -> 1 | B22: COUNTBLANK(Data!B1:B9)
A23: =SUM(Data!A:A) -> 39 | B23: SUM(Data!A:A)
A24: =SUMSQ(Data!A1:A3) -> 98 | B24: SUMSQ(Data!A1:A3)
A25: =STDEV(Data!A1:A8) -> 2.9001232 | B25: STDEV(Data!A1:A8)
A26: =VAR(Data!A1:A8) -> 8.4107143 | B26: VAR(Data!A1:A8)
A27: =ROUND(Data!A1/3,2) -> 1.67 | B27: ROUND(Data!A1/3,2)
A28: =ROUND(2.5,0) -> 3 | B28: ROUND(2.5,0)
A29: =ROUND(-2.5,0) -> -3 | B29: ROUND(-2.5,0)
A30: =ROUND(1.005,2) -> 1.01 | B30: ROUND(1.005,2)
A31: =ROUND(1234.567,-2) -> 1200 | B31: ROUND(1234.567,-2)
A32: =ROUNDUP(2.341,2) -> 2.35 | B32: ROUNDUP(2.341,2)
A33: =ROUNDDOWN(-2.349,2) -> -2.34 | B33: ROUNDDOWN(-2.349,2)
A34: =TRUNC(8.97) -> 8 | B34: TRUNC(8.97)
A35: =TRUNC(8.97,1) -> 8.9 | B35: TRUNC(8.97,1)
A36: =INT(-3.2) -> -4 | B36: INT(-3.2)
A37: =MOD(-7,3) -> 2 | B37: MOD(-7,3)
A38: =MOD(7,-3) -> -2 | B38: MOD(7,-3)
A39: =POWER(2,10) -> 1024 | B39: POWER(2,10)
A40: =SQRT(16) -> 4 | B40: SQRT(16)
...
